Workbook
Name Print_Area: Расчёт_м_м!$B$2:$D$81
Name Print_Area: Расчеты_благо!$A$2:$G$81

Sheet ГП
C1: Интерполяция
B2: исходные | F2: конечные
B3: x0 | C3: x1 | D3: х2 | F3: f(x0) | G3: f(x1) | H3: f(x2)
A4: ПОС,здание+мелкий материал | B4: 0 | C4: 10 | D4: 10 | F4: 0 | G4: =F4+(C4-B4)*(H4-F4)/(D4-B4) -> 3.5 | H4: 3.5
A5: ПОС,здание+мелкий материал | B5: 10 | C5: 12 | D5: 20 | F5: 3.5 | G5: =F5+(C5-B5)*(H5-F5)/(D5-B5) -> 3.8 | H5: 5
A6: ПОС,здание+мелкий материал | B6: 20 | C6: 37.8 | D6: 70 | F6: 5 | G6: =F6+(C6-B6)*(H6-F6)/(D6-B6) -> 5.712 | H6: 7
A7: ПОС,кран+груз | B7: 10 | C7: 10 | D7: 20 | F7: 4 | G7: =F7+(C7-B7)*(H7-F7)/(D7-B7) -> 4 | H7: 7
A8: ПОС,кран+груз | B8: 20 | C8: 36 | D8: 70 | F8: 7 | G8: =F8+(C8-B8)*(H8-F8)/(D8-B8) -> 7.96 | H8: 10
A10: ПЗУ, машиноместа | C10: <= | D10: 10 | G10: 10
A11: ПЗУ, машиноместа | B11: 10 | C11: 30 | D11: 50 | F11: 10 | G11: =F11+(C11-B11)*(H11-F11)/(D11-B11) -> 12.5 | H11: 15
A12: ПЗУ, машиноместа | B12: 10 | C12: 36 | D12: 50 | F12: 10 | G12: =F12+(C12-B12)*(H12-F12)/(D12-B12) -> 13.25 | H12: 15
A13: ПЗУ, машиноместа | B13: 50 | C13: 60 | D13: 100 | F13: 15 | G13: =F13+(C13-B13)*(H13-F13)/(D13-B13) -> 17 | H13: 25
A14: ПЗУ, машиноместа | B14: 100 | C14: 134 | D14: 300 | F14: 25 | G14: =F14+(C14-B14)*(H14-F14)/(D14-B14) -> 26.7 | H14: 35
A15: ПЗУ, машиноместа | B15: 100 | C15: 234 | D15: 300 | F15: 25 | G15: =F15+(C15-B15)*(H15-F15)/(D15-B15) -> 31.7 | H15: 35
A16: ПЗУ, машиноместа | B16: 100 | C16: 255 | D16: 300 | F16: 25 | G16: =F16+(C16-B16)*(H16-F16)/(D16-B16) -> 32.75 | H16: 35
A17: ПЗУ, машиноместа | B17: 300 | C17: >= | G17: 50
B20: 2 | C20: 10
B21: 3.6 | C21: 2.5
C23: =B21*B20+C21*C20 -> 32.2 | E23: =C25+C20+B20 -> 24.88
C25: =C23/C26 -> 12.88
C26: 2.5
E27: =30*2.5 -> 75
D32: 10 | E32: 10
D33: =(D32^2+E32^2)/((E32+D32)^(0.5)) -> 44.72136
A35: ПЗУ, машиноместа-ДП | C35: <= | D35: 10 | G35: 25
A36: ПЗУ, машиноместа-ДП | B36: 10 | C36: 12 | D36: 50 | F36: 25 | G36: =F36+(C36-B36)*(H36-F36)/(D36-B36) -> 26.25 | H36: 50
A37: ПЗУ, машиноместа-ДП | B37: 10 | C37: 23 | D37: 50 | G37: 50
A38: ПЗУ, машиноместа-ДП | C38: >= | D38: 50 | G38: 50
A39: ПЗУ, машиноместа-ДП | C39: >= | D39: 100 | G39: 50
A45: МГН | C45: 44 | D45: =IF(C45<100,ROUNDUP(C45*0.05,0.1),IF(C45<200,5+ROUNDUP((C45-100)*0.03,0.1),IF(C45<500,8+ROUNDUP((C45-200)*0.02,0.1),IF(C45+500,14+ROUNDUP((C45-500)*0.01,0.1))))) -> 3

Sheet Таблицы
A1: Уточняющий коэффициент деловой активности территории города Москвы для расчета числа мест приобъектной парковки К2
A2: №п/п | B2: Район города Москвы | C2: Внутри ТТК | D2: Снаружи ТТК | I2: Внутри ТТК | J2: 1
A3: 1 | B3: 2 | C3: 3 | D3: 4 | I3: За пределами ТТК | J3: 0
A4: 1 | B4: Академический | C4: 0.7 | D4: =C4 -> 0.7
A5: 2 | B5: Алексеевский | C5: 0.5 | D5: =C5 -> 0.5
A6: 3 | B6: Алтуфьевский | C6: 0.9 | D6: =C6 -> 0.9
A7: 4 | B7: Арбат | C7: 0.2 | D7: =C7 -> 0.2
A8: 5 | B8: Аэропорт | C8: 0.5 | D8: =C8 -> 0.5
A9: 6 | B9: Бабушкинский | C9: 0.9 | D9: =C9 -> 0.9
A10: 7 | B10: Басманный | C10: 0.2 | D10: 0.5
A11: 8 | B11: Беговой | C11: 0.2 | D11: 0.5
A12: 9 | B12: Бекасово | C12: 0.9 | D12: =C12 -> 0.9
A13: 10 | B13: Бескудниковский | C13: 0.9 | D13: =C13 -> 0.9
A14: 11 | B14: Бибирево | C14: 0.9 | D14: =C14 -> 0.9
A15: 12 | B15: Бирюлёво Восточное | C15: 0.9 | D15: =C15 -> 0.9
A16: 13 | B16: Бирюлёво Западное | C16: 0.9 | D16: =C16 -> 0.9
A17: 14 | B17: Богородское | C17: 0.9 | D17: =C17 -> 0.9
A18: 15 | B18: Братеево | C18: 0.9 | D18: =C18 -> 0.9
A19: 16 | B19: Бутово Северное | C19: 0.9 | D19: =C19 -> 0.9
A20: 17 | B20: Бутово Южное | C20: 0.9 | D20: =C20 -> 0.9
A21: 18 | B21: Бутырский | C21: 0.5 | D21: =C21 -> 0.5
A22: 19 | B22: Вешняки | C22: 0.9 | D22: =C22 -> 0.9
A23: 20 | B23: Внуково | C23: 0.7 | D23: =C23 -> 0.7
... A32: 29 | B32: Гольяново | C32: 0.9 | D32: =C32 -> 0.9
A33: 30 | B33: Даниловский | C33: 0.2 | D33: 0.5
A34: 31 | B34: Дмитровский | C34: 0.9 | D34: =C34 -> 0.9
A35: 32 | B35: Донской | C35: 0.2 | D35: 0.5
A36: 33 | B36: Дорогомилово | C36: 0.2 | D36: 0.5
A37: 34 | B37: Замоскворечье | C37: 0.2 | D37: =C37 -> 0.2
A38: 35 | B38: Западное Дегунино | C38: 0.9 | D38: =C38 -> 0.9
A39: 36 | B39: Зюзино | C39: 0.9 | D39: =C39 -> 0.9
A40: 37 | B40: Зябликово | C40: 0.9 | D40: =C40 -> 0.9
A41: 38 | B41: Ивановское | C41: 0.9 | D41: =C41 -> 0.9
A42: 39 | B42: Измайлово | C42: 0.9 | D42: =C42 -> 0.9
A43: 40 | B43: Капотня | C43: 0.9 | D43: =C43 -> 0.9
A44: 41 | B44: Коммунарка | C44: 0.7 | D44: =C44 -> 0.7
A45: 42 | B45: Коньково | C45: 0.7 | D45: =C45 -> 0.7
A46: 43 | B46: Коптево | C46: 0.9 | D46: =C46 -> 0.9
A47: 44 | B47: Косино-Ухтомский | C47: 0.9 | D47: =C47 -> 0.9
A48: 45 | B48: Котловка | C48: 0.9 | D48: =C48 -> 0.9
...

Sheet Исходные данные
A2: №п/п | B2: Наименование | C2: Тип объекта | D2: Год РНС | E2: Площадь участка проектирования | F2: Суммарная поэтажная жилой части, кв.м (СПП жилой части) | G2: Площадь квартир, кв.м | H2: Суммарная поэтажная площадь помещений общественного назначения, кв.м (СПП НПКИ) | I2: Общая площадь помещений общественного назначения (НПКИ), кв.м | J2: Нежилая наземная площадь (ННП) | K2: Район города Москвы | L2: Место площадки относительно ТТК г.Москва | M2: Доступность рельсового каркаса
D3: г. | E3: кв.м | F3: S | G3: Sоб.кв. | H3: X | I3: Sнпки | J3: X
A4: =IF(COUNTIF(B$3:B4,B4)=1,MAX(A$1:A3)+1,"") -> 1 | B4: Строгино_Среда_к1 | C4: Многоквартирный дом (2.1.1, 2.5, 2.6) | D4: 2027 и далее | E4: 17779.81 | F4: - | G4: 32103 | H4: - | I4: 2123 | J4: =I4 -> 2123 | K4: Строгино | L4: Снаружи ТТК | M4: более 2 200 м (более 30 мин. пешком)
A5: =IF(COUNTIF(B$3:B5,B5)=1,MAX(A$1:A4)+1,"") -> 2 | B5: Строгино_Среда_к2 | C5: Многоквартирный дом (2.1.1, 2.5, 2.6) | D5: 2027 и далее | E5: 17268.05 | F5: - | G5: =G6+G7 -> 47520 | H5: - | I5: =I6+I7 -> 2487 | J5: =I5 -> 2487 | K5: Строгино | L5: Снаружи ТТК | M5: более 2 200 м (более 30 мин. пешком)
A6: =IF(COUNTIF(B$3:B6,B6)=1,MAX(A$1:A5)+1,"") -> 3 | B6: Строгино_Среда_к2.1 | C6: Многоквартирный дом (2.1.1, 2.5, 2.6) | D6: 2027 и далее | E6: 12150 | F6: - | G6: 30089 | H6: - | I6: 1120 | J6: =I6 -> 1120 | K6: Строгино | L6: Снаружи ТТК | M6: более 2 200 м (более 30 мин. пешком)
A7: =IF(COUNTIF(B$3:B7,B7)=1,MAX(A$1:A6)+1,"") -> 4 | B7: Строгино_Среда_к2.2 | C7: Многоквартирный дом (2.1.1, 2.5, 2.6) | D7: 2027 и далее | E7: =E5-E6 -> 5118.05 | F7: - | G7: 17431 | H7: - | I7: 1367 | J7: =I7 -> 1367 | K7: Строгино | L7: Снаружи ТТК | M7: более 2 200 м (более 30 мин. пешком)
A8: =IF(COUNTIF(B$3:B8,B8)=1,MAX(A$1:A7)+1,"") -> 5 | B8: Строгино_Среда_к3 | C8: Многоквартирный дом (2.1.1, 2.5, 2.6) | D8: 2026 | E8: 24274.11 | F8: - | G8: =G9+G10 -> 51539.3 | H8: - | I8: =I9+I10 -> 3020.54 | J8: =J9+J10 -> 4048 | K8: Строгино | L8: Снаружи ТТК | M8: более 2 200 м (более 30 мин. пешком)
A9: =IF(COUNTIF(B$3:B9,B9)=1,MAX(A$1:A8)+1,"") -> 6 | B9: Строгино_Среда_к3.1-3.4 | C9: Многоквартирный дом (2.1.1, 2.5, 2.6) | D9: 2026 | E9: 16700 | F9: - | G9: 28124.7 | H9: - | I9: 1998.51 | J9: 2757.4 | K9: Строгино | L9: Снаружи ТТК | M9: более 2 200 м (более 30 мин. пешком)
A10: =IF(COUNTIF(B$3:B10,B10)=1,MAX(A$1:A9)+1,"") -> 7 | B10: Строгино_Среда_к3.4-3.7 | C10: Многоквартирный дом (2.1.1, 2.5, 2.6) | D10: 2027 и далее | E10: =E8-E9 -> 7574.11 | F10: - | G10: 23414.6 | H10: - | I10: 1022.03 | J10: 1290.6 | K10: Строгино | L10: Снаружи ТТК | M10: более 2 200 м (более 30 мин. пешком)
A11: =IF(COUNTIF(B$3:B11,B11)=1,MAX(A$1:A10)+1,"") -> 8 | B11: Строгино_Среда_к4 | C11: Многоквартирный дом (2.1.1, 2.5, 2.6) | D11: 2027 и далее | E11: 24532.67 | F11: - | G11: =G12+G13 -> 55124 | H11: - | I11: =I12+I13 -> 4801 | J11: =J12+J13 -> 4801 | K11: Строгино | L11: Снаружи ТТК | M11: более 2 200 м (более 30 мин. пешком)
A12: =IF(COUNTIF(B$3:B12,B12)=1,MAX(A$1:A11)+1,"") -> 9 | B12: Строгино_Среда_к4.1 | C12: Многоквартирный дом (2.1.1, 2.5, 2.6) | D12: 2027 и далее | E12: 16100 | F12: - | G12: 24133 | H12: - | I12: 3466 | J12: 3466 | K12: Строгино | L12: Снаружи ТТК | M12: более 2 200 м (более 30 мин. пешком)
A13: =IF(COUNTIF(B$3:B13,B13)=1,MAX(A$1:A12)+1,"") -> 10 | B13: Строгино_Среда_к4.2 | C13: Многоквартирный дом (2.1.1, 2.5, 2.6) | D13: 2027 и далее | E13: =E11-E12 -> 8432.67 | F13: - | G13: 30991 | H13: - | I13: 1335 | J13: =I13 -> 1335 | K13: Строгино | L13: Снаружи ТТК | M13: более 2 200 м (более 30 мин. пешком)
A14: =IF(COUNTIF(B$3:B14,B14)=1,MAX(A$1:A13)+1,"")
A15: =IF(COUNTIF(B$3:B15,B15)=1,MAX(A$1:A14)+1,"")
A16: =IF(COUNTIF(B$3:B16,B16)=1,MAX(A$1:A15)+1,"")
A17: =IF(COUNTIF(B$3:B17,B17)=1,MAX(A$1:A16)+1,"")
A18: =IF(COUNTIF(B$3:B18,B18)=1,MAX(A$1:A17)+1,"")
A19: =IF(COUNTIF(B$3:B19,B19)=1,MAX(A$1:A18)+1,"")
A20: =IF(COUNTIF(B$3:B20,B20)=1,MAX(A$1:A19)+1,"")
A21: =IF(COUNTIF(B$3:B21,B21)=1,MAX(A$1:A20)+1,"")
A22: =IF(COUNTIF(B$3:B22,B22)=1,MAX(A$1:A21)+1,"")
A23: =IF(COUNTIF(B$3:B23,B23)=1,MAX(A$1:A22)+1,"")
A24: =IF(COUNTIF(B$3:B24,B24)=1,MAX(A$1:A23)+1,"")
A25: =IF(COUNTIF(B$3:B25,B25)=1,MAX(A$1:A24)+1,"")
... A57: =IF(COUNTIF(B$3:B57,B57)=1,MAX(A$1:A56)+1,"")

Sheet Расчёт_м_м
B1: Строгино_Среда_к3 | F1: ='Исходные данные'!$B$4 -> Строгино_Среда_к1 | G1: ='Исходные данные'!$B$5 -> Строгино_Среда_к2 | H1: ='Исходные данные'!$B$6 -> Строгино_Среда_к2.1 | I1: ='Исходные данные'!$B$7 -> Строгино_Среда_к2.2 | J1: ='Исходные данные'!$B$8 -> Строгино_Среда_к3 | K1: ='Исходные данные'!$B$9 -> Строгино_Среда_к3.1-3.4 | L1: ='Исходные данные'!$B$10 -> Строгино_Среда_к3.4-3.7 | M1: ='Исходные данные'!$B$11 -> Строгино_Среда_к4 | N1: ='Исходные данные'!$B$12 -> Строгино_Среда_к4.1 | O1: ='Исходные данные'!$B$13 -> Строгино_Среда_к4.2 | P1: ='Исходные данные'!$B$14 -> 0 | Q1: ='Исходные данные'!$B$15 -> 0 | R1: ='Исходные данные'!$B$16 -> 0
B2: Расчёт стоянок по №945-ПП от 23.12.2015 с изменениями на 17 ноября 2025 года
B3: Наименование показателя | C3: Обозначение | D3: Значение
B4: Тип объекта | D4: =LOOKUP($B$1,E$1:AT$1,E4:AT4) -> Многоквартирный дом (2.1.1, 2.5, 2.6) | F4: ='Исходные данные'!$C$4 -> Многоквартирный дом (2.1.1, 2.5, 2.6) | G4: ='Исходные данные'!$C$5 -> Многоквартирный дом (2.1.1, 2.5, 2.6) | H4: ='Исходные данные'!$C$6 -> Многоквартирный дом (2.1.1, 2.5, 2.6) | I4: ='Исходные данные'!$C$7 -> Многоквартирный дом (2.1.1, 2.5, 2.6) | J4: ='Исходные данные'!$C$8 -> Многоквартирный дом (2.1.1, 2.5, 2.6) | K4: ='Исходные данные'!$C$9 -> Многоквартирный дом (2.1.1, 2.5, 2.6) | L4: ='Исходные данные'!$C$10 -> Многоквартирный дом (2.1.1, 2.5, 2.6) | M4: ='Исходные данные'!$C$11 -> Многоквартирный дом (2.1.1, 2.5, 2.6) | N4: ='Исходные данные'!$C$12 -> Многоквартирный дом (2.1.1, 2.5, 2.6) | O4: ='Исходные данные'!$C$13 -> Многоквартирный дом (2.1.1, 2.5, 2.6) | P4: ='Исходные данные'!$C$14 -> 0 | Q4: ='Исходные данные'!$C$15 -> 0 | R4: ='Исходные данные'!$C$16 -> 0
B5: Год РНС | C5: г. | D5: =LOOKUP($B$1,E$1:AT$1,E5:AT5) -> 2026 | F5: ='Исходные данные'!$D$4 -> 2027 и далее | G5: ='Исходные данные'!$D$5 -> 2027 и далее | H5: ='Исходные данные'!$D$6 -> 2027 и далее | I5: ='Исходные данные'!$D$7 -> 2027 и далее | J5: ='Исходные данные'!$D$8 -> 2026 | K5: ='Исходные данные'!$D$9 -> 2026 | L5: ='Исходные данные'!$D$10 -> 2027 и далее | M5: ='Исходные данные'!$D$11 -> 2027 и далее | N5: ='Исходные данные'!$D$12 -> 2027 и далее | O5: ='Исходные данные'!$D$13 -> 2027 и далее | P5: ='Исходные данные'!$D$14 -> 0 | Q5: ='Исходные данные'!$D$15 -> 0 | R5: ='Исходные данные'!$D$16 -> 0
B6: Площадь участка проектирования | C6: кв.м | D6: =LOOKUP($B$1,E$1:AT$1,E6:AT6) -> 24274.11 | F6: ='Исходные данные'!$E$4 -> 17779.81 | G6: ='Исходные данные'!$E$5 -> 17268.05 | H6: ='Исходные данные'!$E$6 -> 12150 | I6: ='Исходные данные'!$E$7 -> 5118.05 | J6: ='Исходные данные'!$E$8 -> 24274.11 | K6: ='Исходные данные'!$E$9 -> 16700 | L6: ='Исходные данные'!$E$10 -> 7574.11 | M6: ='Исходные данные'!$E$11 -> 24532.67 | N6: ='Исходные данные'!$E$12 -> 16100 | O6: ='Исходные данные'!$E$13 -> 8432.67 | P6: ='Исходные данные'!$E$14 -> 0 | Q6: ='Исходные данные'!$E$15 -> 0 | R6: ='Исходные данные'!$E$16 -> 0
B7: Суммарная поэтажная жилой части, кв.м (СПП жилой части) | C7: S | D7: - | F7: ='Исходные данные'!$F$4 -> - | G7: ='Исходные данные'!$F$5 -> - | H7: ='Исходные данные'!$F$6 -> - | I7: ='Исходные данные'!$F$7 -> - | J7: ='Исходные данные'!$F$8 -> - | K7: ='Исходные данные'!$F$9 -> - | L7: ='Исходные данные'!$F$10 -> - | M7: ='Исходные данные'!$F$11 -> - | N7: ='Исходные данные'!$F$12 -> - | O7: ='Исходные данные'!$F$13 -> - | P7: ='Исходные данные'!$F$14 -> 0 | Q7: ='Исходные данные'!$F$15 -> 0 | R7: ='Исходные данные'!$F$16 -> 0
B8: Площадь квартир, кв.м | C8: Sоб.кв. | D8: =LOOKUP($B$1,E$1:AT$1,E8:AT8) -> 51539.3 | F8: ='Исходные данные'!$G$4 -> 32103 | G8: ='Исходные данные'!$G$5 -> 47520 | H8: ='Исходные данные'!$G$6 -> 30089 | I8: ='Исходные данные'!$G$7 -> 17431 | J8: ='Исходные данные'!$G$8 -> 51539.3 | K8: ='Исходные данные'!$G$9 -> 28124.7 | L8: ='Исходные данные'!$G$10 -> 23414.6 | M8: ='Исходные данные'!$G$11 -> 55124 | N8: ='Исходные данные'!$G$12 -> 24133 | O8: ='Исходные данные'!$G$13 -> 30991 | P8: ='Исходные данные'!$G$14 -> 0 | Q8: ='Исходные данные'!$G$15 -> 0 | R8: ='Исходные данные'!$G$16 -> 0
B9: Суммарная поэтажная площадь помещений общественного назначения, кв.м (СПП НПКИ) | C9: X | D9: - | F9: ='Исходные данные'!$H$4 -> - | G9: ='Исходные данные'!$H$5 -> - | H9: ='Исходные данные'!$H$6 -> - | I9: ='Исходные данные'!$H$7 -> - | J9: ='Исходные данные'!$H$8 -> - | K9: ='Исходные данные'!$H$9 -> - | L9: ='Исходные данные'!$H$10 -> - | M9: ='Исходные данные'!$H$11 -> - | N9: ='Исходные данные'!$H$12 -> - | O9: ='Исходные данные'!$H$13 -> - | P9: ='Исходные данные'!$H$14 -> 0 | Q9: ='Исходные данные'!$H$15 -> 0 | R9: ='Исходные данные'!$H$16 -> 0
B10: Общая площадь помещений общественного назначения (НПКИ), кв.м | C10: Sнпки | D10: =LOOKUP($B$1,E$1:AT$1,E10:AT10) -> 3020.54 | F10: ='Исходные данные'!$I$4 -> 2123 | G10: ='Исходные данные'!$I$5 -> 2487 | H10: ='Исходные данные'!$I$6 -> 1120 | I10: ='Исходные данные'!$I$7 -> 1367 | J10: ='Исходные данные'!$I$8 -> 3020.54 | K10: ='Исходные данные'!$I$9 -> 1998.51 | L10: ='Исходные данные'!$I$10 -> 1022.03 | M10: ='Исходные данные'!$I$11 -> 4801 | N10: ='Исходные данные'!$I$12 -> 3466 | O10: ='Исходные данные'!$I$13 -> 1335 | P10: ='Исходные данные'!$I$14 -> 0 | Q10: ='Исходные данные'!$I$15 -> 0 | R10: ='Исходные данные'!$I$16 -> 0
B11: Нежилая наземная площадь (ННП) | C11: X | D11: =LOOKUP($B$1,E$1:AT$1,E11:AT11) -> 4048 | F11: ='Исходные данные'!$J$4 -> 2123 | G11: ='Исходные данные'!$J$5 -> 2487 | H11: ='Исходные данные'!$J$6 -> 1120 | I11: ='Исходные данные'!$J$7 -> 1367 | J11: ='Исходные данные'!$J$8 -> 4048 | K11: ='Исходные данные'!$J$9 -> 2757.4 | L11: ='Исходные данные'!$J$10 -> 1290.6 | M11: ='Исходные данные'!$J$11 -> 4801 | N11: ='Исходные данные'!$J$12 -> 3466 | O11: ='Исходные данные'!$J$13 -> 1335 | P11: ='Исходные данные'!$J$14 -> 0 | Q11: ='Исходные данные'!$J$15 -> 0 | R11: ='Исходные данные'!$J$16 -> 0
B12: Район города Москвы | D12: Строгино | F12: ='Исходные данные'!$K$4 -> Строгино | G12: ='Исходные данные'!$K$5 -> Строгино | H12: ='Исходные данные'!$K$6 -> Строгино | I12: ='Исходные данные'!$K$7 -> Строгино | J12: ='Исходные данные'!$K$8 -> Строгино | K12: ='Исходные данные'!$K$9 -> Строгино | L12: ='Исходные данные'!$K$10 -> Строгино | M12: ='Исходные данные'!$K$11 -> Строгино | N12: ='Исходные данные'!$K$12 -> Строгино | O12: ='Исходные данные'!$K$13 -> Строгино | P12: ='Исходные данные'!$K$14 -> 0 | Q12: ='Исходные данные'!$K$15 -> 0 | R12: ='Исходные данные'!$K$16 -> 0
B13: Место площадки относительно ТТК г.Москва | D13: =LOOKUP($B$1,E$1:AT$1,E13:AT13) -> Снаружи ТТК | F13: ='Исходные данные'!$L$4 -> Снаружи ТТК | G13: ='Исходные данные'!$L$5 -> Снаружи ТТК | H13: ='Исходные данные'!$L$6 -> Снаружи ТТК | I13: ='Исходные данные'!$L$7 -> Снаружи ТТК | J13: ='Исходные данные'!$L$8 -> Снаружи ТТК | K13: ='Исходные данные'!$L$9 -> Снаружи ТТК | L13: ='Исходные данные'!$L$10 -> Снаружи ТТК | M13: ='Исходные данные'!$L$11 -> Снаружи ТТК | N13: ='Исходные данные'!$L$12 -> Снаружи ТТК | O13: ='Исходные данные'!$L$13 -> Снаружи ТТК | P13: ='Исходные данные'!$L$14 -> 0 | Q13: ='Исходные данные'!$L$15 -> 0 | R13: ='Исходные данные'!$L$16 -> 0
B14: Доступность рельсового каркаса | D14: =LOOKUP($B$1,E$1:AT$1,E14:AT14) -> более 2 200 м (более 30 мин. пешком) | F14: ='Исходные данные'!$M$4 -> более 2 200 м (более 30 мин. пешком) | G14: ='Исходные данные'!$M$5 -> более 2 200 м (более 30 мин. пешком) | H14: ='Исходные данные'!$M$6 -> более 2 200 м (более 30 мин. пешком) | I14: ='Исходные данные'!$M$7 -> более 2 200 м (более 30 мин. пешком) | J14: ='Исходные данные'!$M$8 -> более 2 200 м (более 30 мин. пешком) | K14: ='Исходные данные'!$M$9 -> более 2 200 м (более 30 мин. пешком) | L14: ='Исходные данные'!$M$10 -> более 2 200 м (более 30 мин. пешком) | M14: ='Исходные данные'!$M$11 -> более 2 200 м (более 30 мин. пешком) | N14: ='Исходные данные'!$M$12 -> более 2 200 м (более 30 мин. пешком) | O14: ='Исходные данные'!$M$13 -> более 2 200 м (более 30 мин. пешком) | P14: ='Исходные данные'!$M$14 -> 0 | Q14: ='Исходные данные'!$M$15 -> 0 | R14: ='Исходные данные'!$M$16 -> 0
B15: Коэффициент пешей доступности рельсового каркаса по табл. Приложения 5 | C15: К1 | D15: =LOOKUP(D14,Таблицы!C140:C142,Таблицы!B140:B142) -> 1 | F15: =LOOKUP(F14,Таблицы!$C$140:$C$142,Таблицы!$B$140:$B$142) -> 1 | G15: =LOOKUP(G14,Таблицы!$C$140:$C$142,Таблицы!$B$140:$B$142) -> 1 | H15: =LOOKUP(H14,Таблицы!$C$140:$C$142,Таблицы!$B$140:$B$142) -> 1 | I15: =LOOKUP(I14,Таблицы!$C$140:$C$142,Таблицы!$B$140:$B$142) -> 1 | J15: =LOOKUP(J14,Таблицы!$C$140:$C$142,Таблицы!$B$140:$B$142) -> 1 | K15: =LOOKUP(K14,Таблицы!$C$140:$C$142,Таблицы!$B$140:$B$142) -> 1 | L15: =LOOKUP(L14,Таблицы!$C$140:$C$142,Таблицы!$B$140:$B$142) -> 1 | M15: =LOOKUP(M14,Таблицы!$C$140:$C$142,Таблицы!$B$140:$B$142) -> 1 | ... Q15: =LOOKUP(Q14,Таблицы!$C$140:$C$142,Таблицы!$B$140:$B$142) -> #N/A
B16: Уточняющий коэффициент деловой активности территории города Москвы для расчета числа мест приобъектной парковки по табл. Приложения 6 | C16: К2 | D16: =IF(LOOKUP(D13,Таблицы!$I$2:$I$3,Таблицы!$J$2:$J$3)=1,LOOKUP(D12,Таблицы!$B$4:$B$136,Таблицы!$C$4:$C$136),LOOKUP(D12,Таблицы!$B$4:$B$136,Таблицы!$D$4:$D$136)) -> 0.9 | F16: =IF(LOOKUP(F13,Таблицы!$I$2:$I$3,Таблицы!$J$2:$J$3)=1,LOOKUP(F12,Таблицы!$B$4:$B$136,Таблицы!$C$4:$C$136),LOOKUP(F12,Таблицы!$B$4:$B$136,Таблицы!$D$4:$D$136)) -> 0.9 | G16: =IF(LOOKUP(G13,Таблицы!$I$2:$I$3,Таблицы!$J$2:$J$3)=1,LOOKUP(G12,Таблицы!$B$4:$B$136,Таблицы!$C$4:$C$136),LOOKUP(G12,Таблицы!$B$4:$B$136,Таблицы!$D$4:$D$136)) -> 0.9 | H16: =IF(LOOKUP(H13,Таблицы!$I$2:$I$3,Таблицы!$J$2:$J$3)=1,LOOKUP(H12,Таблицы!$B$4:$B$136,Таблицы!$C$4:$C$136),LOOKUP(H12,Таблицы!$B$4:$B$136,Таблицы!$D$4:$D$136)) -> 0.9 | I16: =IF(LOOKUP(I13,Таблицы!$I$2:$I$3,Таблицы!$J$2:$J$3)=1,LOOKUP(I12,Таблицы!$B$4:$B$136,Таблицы!$C$4:$C$136),LOOKUP(I12,Таблицы!$B$4:$B$136,Таблицы!$D$4:$D$136)) -> 0.9 | J16: =IF(LOOKUP(J13,Таблицы!$I$2:$I$3,Таблицы!$J$2:$J$3)=1,LOOKUP(J12,Таблицы!$B$4:$B$136,Таблицы!$C$4:$C$136),LOOKUP(J12,Таблицы!$B$4:$B$136,Таблицы!$D$4:$D$136)) -> 0.9 | K16: =IF(LOOKUP(K13,Таблицы!$I$2:$I$3,Таблицы!$J$2:$J$3)=1,LOOKUP(K12,Таблицы!$B$4:$B$136,Таблицы!$C$4:$C$136),LOOKUP(K12,Таблицы!$B$4:$B$136,Таблицы!$D$4:$D$136)) -> 0.9 | L16: =IF(LOOKUP(L13,Таблицы!$I$2:$I$3,Таблицы!$J$2:$J$3)=1,LOOKUP(L12,Таблицы!$B$4:$B$136,Таблицы!$C$4:$C$136),LOOKUP(L12,Таблицы!$B$4:$B$136,Таблицы!$D$4:$D$136)) -> 0.9 | M16: =IF(LOOKUP(M13,Таблицы!$I$2:$I$3,Таблицы!$J$2:$J$3)=1,LOOKUP(M12,Таблицы!$B$4:$B$136,Таблицы!$C$4:$C$136),LOOKUP(M12,Таблицы!$B$4:$B$136,Таблицы!$D$4:$D$136)) -> 0.9 | ... Q16: =IF(LOOKUP(Q13,Таблицы!$I$2:$I$3,Таблицы!$J$2:$J$3)=1,LOOKUP(Q12,Таблицы!$B$4:$B$136,Таблицы!$C$4:$C$136),LOOKUP(Q12,Таблицы!$B$4:$B$136,Таблицы!$D$4:$D$136)) -> #N/A
B17: Расчета числа мест постоянного размещения транспортных средств жителей
B18: Показатели расчета населения по типам жилой застройки | C18: S1 | D18: =LOOKUP($B$1,E$1:AT$1,E18:AT18) -> 33 | F18: =LOOKUP(F4,Таблицы!$B169:$B171,Таблицы!$D169:$D171) -> 33 | G18: =LOOKUP(G4,Таблицы!$B169:$B171,Таблицы!$D169:$D171) -> 33 | H18: =LOOKUP(H4,Таблицы!$B169:$B171,Таблицы!$D169:$D171) -> 33 | I18: =LOOKUP(I4,Таблицы!$B169:$B171,Таблицы!$D169:$D171) -> 33 | J18: =LOOKUP(J4,Таблицы!$B169:$B171,Таблицы!$D169:$D171) -> 33 | K18: =LOOKUP(K4,Таблицы!$B169:$B171,Таблицы!$D169:$D171) -> 33 | L18: =LOOKUP(L4,Таблицы!$B169:$B171,Таблицы!$D169:$D171) -> 33 | M18: =LOOKUP(M4,Таблицы!$B169:$B171,Таблицы!$D169:$D171) -> 33 | ... Q18: =LOOKUP(Q4,Таблицы!$B169:$B171,Таблицы!$D169:$D171) -> #N/A
B19: Целевой показатель уровня автомобилизации города Москвы — 257 транспортных средств на 1 000 жителей по Приложению 5 | C19: А | D19: 0.257 | F19: =$D19 -> 0.257 | G19: =$D19 -> 0.257 | H19: =$D19 -> 0.257 | I19: =$D19 -> 0.257 | J19: =$D19 -> 0.257 | K19: =$D19 -> 0.257 | L19: =$D19 -> 0.257 | M19: =$D19 -> 0.257 | ... Q19: =$D19 -> 0.257
A20: =ROUNDUP((D8/D18)*D19*D15,0) -> 402 | B20: ="Nп= (S/S1) × A × К1 = ("&D8&" / "&D18&") x "&D19&" x "&D15&" ="&ROUNDUP((D8/D18)*D19*D15,0)&" (шт.)" -> Nп= (S/S1) × A × К1 = (51539.3 / 33) x 0.257 x 1 =402 (шт.) | F20: =ROUNDUP((F8/F18)*F19*F15,0) -> 251 | G20: =ROUNDUP((G8/G18)*G19*G15,0) -> 371 | H20: =ROUNDUP((H8/H18)*H19*H15,0) -> 235 | I20: =ROUNDUP((I8/I18)*I19*I15,0) -> 136 | J20: =ROUNDUP((J8/J18)*J19*J15,0) -> 402 | K20: =ROUNDUP((K8/K18)*K19*K15,0) -> 220 | L20: =ROUNDUP((L8/L18)*L19*L15,0) -> 183 | M20: =ROUNDUP((M8/M18)*M19*M15,0) -> 430 | ... Q20: =ROUNDUP((Q8/Q18)*Q19*Q15,0) -> #N/A
A21: =ROUNDUP(A20*0.9,0) -> 362 | B21: ="Nп-10%= Nп х 90% = "&A20&" х 90% = "&ROUNDUP(A20*0.9,0)&" (шт.) - с учётом допустимого отклонения 10%" -> Nп-10%= Nп х 90% = 402 х 90% = 362 (шт.) - с учётом допустимого отклонения 10% | F21: =ROUNDUP(F20*0.9,0) -> 226 | G21: =ROUNDUP(G20*0.9,0) -> 334 | H21: =ROUNDUP(H20*0.9,0) -> 212 | I21: =ROUNDUP(I20*0.9,0) -> 123 | J21: =ROUNDUP(J20*0.9,0) -> 362 | K21: =ROUNDUP(K20*0.9,0) -> 198 | L21: =ROUNDUP(L20*0.9,0) -> 165 | M21: =ROUNDUP(M20*0.9,0) -> 387 | ... Q21: =ROUNDUP(Q20*0.9,0) -> #N/A
A22: =ROUNDDOWN(A20*1.1,0) -> 442 | B22: ="Nп+10%= Nп х 110% = "&A20&" х 110% = "&ROUNDDOWN(A20*1.1,0)&" (шт.) - с учётом допустимого отклонения 10%" -> Nп+10%= Nп х 110% = 402 х 110% = 442 (шт.) - с учётом допустимого отклонения 10% | F22: =ROUNDDOWN(F20*1.1,0) -> 276 | G22: =ROUNDDOWN(G20*1.1,0) -> 408 | H22: =ROUNDDOWN(H20*1.1,0) -> 258 | I22: =ROUNDDOWN(I20*1.1,0) -> 149 | J22: =ROUNDDOWN(J20*1.1,0) -> 442 | K22: =ROUNDDOWN(K20*1.1,0) -> 242 | L22: =ROUNDDOWN(L20*1.1,0) -> 201 | M22: =ROUNDDOWN(M20*1.1,0) -> 473 | ... Q22: =ROUNDDOWN(Q20*1.1,0) -> #N/A
B23: Квартиры для МГН по заданию на проектирование не предусматриваются. Стоянки МГН постоянного хранения не требуются.
B24: Расчет числа мест гостевой парковки (допустимо отклонение 10%)
A25: =ROUNDUP(A20*0.1,0) -> 41 | B25: ="Nг= Nп х 10% = "&A20&" х 10% = "&ROUNDUP(A20*0.1,0)&" (шт.)" -> Nг= Nп х 10% = 402 х 10% = 41 (шт.) | F25: =ROUNDUP(F20*0.1,0) -> 26 | G25: =ROUNDUP(G20*0.1,0) -> 38 | H25: =ROUNDUP(H20*0.1,0) -> 24 | I25: =ROUNDUP(I20*0.1,0) -> 14 | J25: =ROUNDUP(J20*0.1,0) -> 41 | K25: =ROUNDUP(K20*0.1,0) -> 22 | L25: =ROUNDUP(L20*0.1,0) -> 19 | M25: =ROUNDUP(M20*0.1,0) -> 43 | ... Q25: =ROUNDUP(Q20*0.1,0) -> #N/A
A26: =ROUNDUP(A25*0.9,0) -> 37 | B26: ="Nг-10%= Nг х 90% = "&A25&" х 90% = "&ROUNDUP(A25*0.9,0)&" (шт.) - с учётом допустимого отклонения 10%" -> Nг-10%= Nг х 90% = 41 х 90% = 37 (шт.) - с учётом допустимого отклонения 10% | F26: =ROUNDUP(F25*0.9,0) -> 24 | G26: =ROUNDUP(G25*0.9,0) -> 35 | H26: =ROUNDUP(H25*0.9,0) -> 22 | I26: =ROUNDUP(I25*0.9,0) -> 13 | J26: =ROUNDUP(J25*0.9,0) -> 37 | K26: =ROUNDUP(K25*0.9,0) -> 20 | L26: =ROUNDUP(L25*0.9,0) -> 18 | M26: =ROUNDUP(M25*0.9,0) -> 39 | ... Q26: =ROUNDUP(Q25*0.9,0) -> #N/A
A27: =ROUNDDOWN(A25*1.1,0) -> 45 | B27: ="Nг+10%= Nг х 110% = "&A25&" х 110% = "&ROUNDDOWN(A25*1.1,0)&" (шт.) - с учётом допустимого отклонения 10%" -> Nг+10%= Nг х 110% = 41 х 110% = 45 (шт.) - с учётом допустимого отклонения 10% | F27: =ROUNDDOWN(F25*1.1,0) -> 28 | G27: =ROUNDDOWN(G25*1.1,0) -> 41 | H27: =ROUNDDOWN(H25*1.1,0) -> 26 | I27: =ROUNDDOWN(I25*1.1,0) -> 15 | J27: =ROUNDDOWN(J25*1.1,0) -> 45 | K27: =ROUNDDOWN(K25*1.1,0) -> 24 | L27: =ROUNDDOWN(L25*1.1,0) -> 20 | M27: =ROUNDDOWN(M25*1.1,0) -> 47 | ... Q27: =ROUNDDOWN(Q25*1.1,0) -> #N/A
A28: =ROUNDUP(A25*0.1,0) -> 5 | B28: ="Из них для МГН: Nг(МГН)= Nг х 10% = "&A25&" х 90% = "&A28&" (шт.), в т.ч. увеличенных размеров: "&A29&" (шт.) - не далее 100м, либо не далее 200м от входной группы с устройством промежуточных площадок с навесами каждые 100м и кратковременной остановкой не далее 50м от входа" -> Из них для МГН: Nг(МГН)= Nг х 10% = 41 х 90% = 5 (шт.), в т.ч. увеличенных размеров: 3 (шт.) - не далее 100м, либо не далее 200м от входной группы с устройством промежуточных площадок с навесами каждые 100м и кратковременной остановкой не далее 50м от входа | F28: =ROUNDUP(F25*0.1,0) -> 3 | G28: =ROUNDUP(G25*0.1,0) -> 4 | H28: =ROUNDUP(H25*0.1,0) -> 3 | I28: =ROUNDUP(I25*0.1,0) -> 2 | J28: =ROUNDUP(J25*0.1,0) -> 5 | K28: =ROUNDUP(K25*0.1,0) -> 3 | L28: =ROUNDUP(L25*0.1,0) -> 2 | M28: =ROUNDUP(M25*0.1,0) -> 5 | ... Q28: =ROUNDUP(Q25*0.1,0) -> #N/A
A29: =IF(A25<=100,ROUNDUP(A25*0.05,0),IF(A25<=200,5+ROUNDUP((A25-100)*0.03,0),IF(A25<=500,8+ROUNDUP((A25-200)*0.02,0),14+ROUNDUP((A25-500)*0.01,0)))) -> 3 | B29: Расчет числа мест приобъектной парковки встроенно-пристроенных коммерческих помещений (допустимо отклонение +-30%); согласно прим. 4. к таблице Приложения 1 - при размерах суммарной поэтажной площади торговых объектов менее 500 кв.м парковочные места и (или) машино-места допускается не предусматривать | F29: =IF(F25<=100,ROUNDUP(F25*0.05,0),IF(F25<=200,5+ROUNDUP((F25-100)*0.03,0),IF(F25<=500,8+ROUNDUP((F25-200)*0.02,0),14+ROUNDUP((F25-500)*0.01,0)))) -> 2 | G29: =IF(G25<=100,ROUNDUP(G25*0.05,0),IF(G25<=200,5+ROUNDUP((G25-100)*0.03,0),IF(G25<=500,8+ROUNDUP((G25-200)*0.02,0),14+ROUNDUP((G25-500)*0.01,0)))) -> 2 | H29: =IF(H25<=100,ROUNDUP(H25*0.05,0),IF(H25<=200,5+ROUNDUP((H25-100)*0.03,0),IF(H25<=500,8+ROUNDUP((H25-200)*0.02,0),14+ROUNDUP((H25-500)*0.01,0)))) -> 2 | I29: =IF(I25<=100,ROUNDUP(I25*0.05,0),IF(I25<=200,5+ROUNDUP((I25-100)*0.03,0),IF(I25<=500,8+ROUNDUP((I25-200)*0.02,0),14+ROUNDUP((I25-500)*0.01,0)))) -> 1 | J29: =IF(J25<=100,ROUNDUP(J25*0.05,0),IF(J25<=200,5+ROUNDUP((J25-100)*0.03,0),IF(J25<=500,8+ROUNDUP((J25-200)*0.02,0),14+ROUNDUP((J25-500)*0.01,0)))) -> 3 | K29: =IF(K25<=100,ROUNDUP(K25*0.05,0),IF(K25<=200,5+ROUNDUP((K25-100)*0.03,0),IF(K25<=500,8+ROUNDUP((K25-200)*0.02,0),14+ROUNDUP((K25-500)*0.01,0)))) -> 2 | L29: =IF(L25<=100,ROUNDUP(L25*0.05,0),IF(L25<=200,5+ROUNDUP((L25-100)*0.03,0),IF(L25<=500,8+ROUNDUP((L25-200)*0.02,0),14+ROUNDUP((L25-500)*0.01,0)))) -> 1 | M29: =IF(M25<=100,ROUNDUP(M25*0.05,0),IF(M25<=200,5+ROUNDUP((M25-100)*0.03,0),IF(M25<=500,8+ROUNDUP((M25-200)*0.02,0),14+ROUNDUP((M25-500)*0.01,0)))) -> 3 | ... Q29: =IF(Q25<=100,ROUNDUP(Q25*0.05,0),IF(Q25<=200,5+ROUNDUP((Q25-100)*0.03,0),IF(Q25<=500,8+ROUNDUP((Q25-200)*0.02,0),14+ROUNDUP((Q25-500)*0.01,0)))) -> #N/A
B30: Расчетный показатель в расчетных единицах на одно парковочное место и машино-место в соответствии с примечанием 1 к Приложению 6, кв.м | C30: X2 | D30: 90 | F30: =$D30 -> 90 | G30: =$D30 -> 90 | H30: =$D30 -> 90 | I30: =$D30 -> 90 | J30: =$D30 -> 90 | K30: =$D30 -> 90 | L30: =$D30 -> 90 | M30: =$D30 -> 90 | ... Q30: =$D30 -> 90
A31: =ROUNDUP((D11/D30)*D15*D16,0) -> 41 | B31: ="Nв = X / Х2 x K1 x K2 = ("&D11&" / "&D30&") x "&D15&" x "&D16&" = "&ROUNDUP((D11/D30)*D15*D16,0)&" (шт.)" -> Nв = X / Х2 x K1 x K2 = (4048 / 90) x 1 x 0.9 = 41 (шт.) | F31: =ROUNDUP((F11/F30)*F15*F16,0) -> 22 | G31: =ROUNDUP((G11/G30)*G15*G16,0) -> 25 | H31: =ROUNDUP((H11/H30)*H15*H16,0) -> 12 | I31: =ROUNDUP((I11/I30)*I15*I16,0) -> 14 | J31: =ROUNDUP((J11/J30)*J15*J16,0) -> 41 | K31: =ROUNDUP((K11/K30)*K15*K16,0) -> 28 | L31: =ROUNDUP((L11/L30)*L15*L16,0) -> 13 | M31: =ROUNDUP((M11/M30)*M15*M16,0) -> 49 | ... Q31: =ROUNDUP((Q11/Q30)*Q15*Q16,0) -> #N/A
A32: =ROUNDUP(A31*0.7,0) -> 29 | B32: ="Nв-30%= Nв х 70% = "&A31&" х 70% = "&ROUNDUP(A31*0.7,0)&" (шт.) - с учётом допустимого отклонения 30%" -> Nв-30%= Nв х 70% = 41 х 70% = 29 (шт.) - с учётом допустимого отклонения 30% | F32: =ROUNDUP(F31*0.7,0) -> 16 | G32: =ROUNDUP(G31*0.7,0) -> 18 | H32: =ROUNDUP(H31*0.7,0) -> 9 | I32: =ROUNDUP(I31*0.7,0) -> 10 | J32: =ROUNDUP(J31*0.7,0) -> 29 | K32: =ROUNDUP(K31*0.7,0) -> 20 | L32: =ROUNDUP(L31*0.7,0) -> 10 | M32: =ROUNDUP(M31*0.7,0) -> 35 | ... Q32: =ROUNDUP(Q31*0.7,0) -> #N/A
A33: =ROUNDDOWN(A31*1.3,0) -> 53 | B33: ="Nв+30%= Nв х 130% = "&A32&" х 130% = "&ROUNDDOWN(A31*1.3,0)&" (шт.) - с учётом допустимого отклонения 30%" -> Nв+30%= Nв х 130% = 29 х 130% = 53 (шт.) - с учётом допустимого отклонения 30% | F33: =ROUNDDOWN(F31*1.3,0) -> 28 | G33: =ROUNDDOWN(G31*1.3,0) -> 32 | H33: =ROUNDDOWN(H31*1.3,0) -> 15 | I33: =ROUNDDOWN(I31*1.3,0) -> 18 | J33: =ROUNDDOWN(J31*1.3,0) -> 53 | K33: =ROUNDDOWN(K31*1.3,0) -> 36 | L33: =ROUNDDOWN(L31*1.3,0) -> 16 | M33: =ROUNDDOWN(M31*1.3,0) -> 63 | ... Q33: =ROUNDDOWN(Q31*1.3,0) -> #N/A
A34: =ROUNDUP(A31*0.1,0) -> 5 | B34: ="Из них для МГН: Nв(МГН)= Nв х 10% = "&A31&" х 10% = "&A34&" (шт.), в т.ч. увеличенных размеров: "&A35&" (шт.) - не далее 50м, либо не далее 200м от входной группы с устройством промежуточных площадок с навесами каждые 100м и кратковременной остановкой не далее 50м от входа" -> Из них для МГН: Nв(МГН)= Nв х 10% = 41 х 10% = 5 (шт.), в т.ч. увеличенных размеров: 3 (шт.) - не далее 50м, либо не далее 200м от входной группы с устройством промежуточных площадок с навесами каждые 100м и кратковременной остановкой не далее 50м от входа | F34: =ROUNDUP(F31*0.1,0) -> 3 | G34: =ROUNDUP(G31*0.1,0) -> 3 | H34: =ROUNDUP(H31*0.1,0) -> 2 | I34: =ROUNDUP(I31*0.1,0) -> 2 | J34: =ROUNDUP(J31*0.1,0) -> 5 | K34: =ROUNDUP(K31*0.1,0) -> 3 | L34: =ROUNDUP(L31*0.1,0) -> 2 | M34: =ROUNDUP(M31*0.1,0) -> 5 | ... Q34: =ROUNDUP(Q31*0.1,0) -> #N/A
A35: =IF(A31<=100,ROUNDUP(A31*0.05,0),IF(A31<=200,5+ROUNDUP((A31-100)*0.03,0),IF(A31<=500,8+ROUNDUP((A31-200)*0.02,0),14+ROUNDUP((A31-500)*0.01,0)))) -> 3 | B35: Расчет числа мест остановки (размер одного места не менее 6,0 х 3,6 метра или 2,5 х 6,5 метра, в случае расположения вдоль проезжей части) | F35: =IF(F31<=100,ROUNDUP(F31*0.05,0),IF(F31<=200,5+ROUNDUP((F31-100)*0.03,0),IF(F31<=500,8+ROUNDUP((F31-200)*0.02,0),14+ROUNDUP((F31-500)*0.01,0)))) -> 2 | G35: =IF(G31<=100,ROUNDUP(G31*0.05,0),IF(G31<=200,5+ROUNDUP((G31-100)*0.03,0),IF(G31<=500,8+ROUNDUP((G31-200)*0.02,0),14+ROUNDUP((G31-500)*0.01,0)))) -> 2 | H35: =IF(H31<=100,ROUNDUP(H31*0.05,0),IF(H31<=200,5+ROUNDUP((H31-100)*0.03,0),IF(H31<=500,8+ROUNDUP((H31-200)*0.02,0),14+ROUNDUP((H31-500)*0.01,0)))) -> 1 | I35: =IF(I31<=100,ROUNDUP(I31*0.05,0),IF(I31<=200,5+ROUNDUP((I31-100)*0.03,0),IF(I31<=500,8+ROUNDUP((I31-200)*0.02,0),14+ROUNDUP((I31-500)*0.01,0)))) -> 1 | J35: =IF(J31<=100,ROUNDUP(J31*0.05,0),IF(J31<=200,5+ROUNDUP((J31-100)*0.03,0),IF(J31<=500,8+ROUNDUP((J31-200)*0.02,0),14+ROUNDUP((J31-500)*0.01,0)))) -> 3 | K35: =IF(K31<=100,ROUNDUP(K31*0.05,0),IF(K31<=200,5+ROUNDUP((K31-100)*0.03,0),IF(K31<=500,8+ROUNDUP((K31-200)*0.02,0),14+ROUNDUP((K31-500)*0.01,0)))) -> 2 | L35: =IF(L31<=100,ROUNDUP(L31*0.05,0),IF(L31<=200,5+ROUNDUP((L31-100)*0.03,0),IF(L31<=500,8+ROUNDUP((L31-200)*0.02,0),14+ROUNDUP((L31-500)*0.01,0)))) -> 1 | M35: =IF(M31<=100,ROUNDUP(M31*0.05,0),IF(M31<=200,5+ROUNDUP((M31-100)*0.03,0),IF(M31<=500,8+ROUNDUP((M31-200)*0.02,0),14+ROUNDUP((M31-500)*0.01,0)))) -> 3 | ... Q35: =IF(Q31<=100,ROUNDUP(Q31*0.05,0),IF(Q31<=200,5+ROUNDUP((Q31-100)*0.03,0),IF(Q31<=500,8+ROUNDUP((Q31-200)*0.02,0),14+ROUNDUP((Q31-500)*0.01,0)))) -> #N/A
B36: Функциональное назначение объекта | C36: Жилое назначение
B37: Показатель суммарной поэтажной площади объекта на одно место остановки в соответствии с таблицей к Приложению 8 | C37: S1 | D37: =LOOKUP(C36,Таблицы!B148:B153,Таблицы!D148:D153) -> 22100 | F37: =$D37 -> 22100 | G37: =$D37 -> 22100 | H37: =$D37 -> 22100 | I37: =$D37 -> 22100 | J37: =$D37 -> 22100 | K37: =$D37 -> 22100 | L37: =$D37 -> 22100 | M37: =$D37 -> 22100 | ... Q37: =$D37 -> 22100
A38: =ROUNDUP((D8/D37),0) -> 3 | B38: ="Nк = S/S1 = ("&D8&" / "&D37&") ="&ROUNDUP((D8/D37),0)&" (шт.)" -> Nк = S/S1 = (51539.3 / 22100) =3 (шт.) | F38: =ROUNDUP((F8/F37),0) -> 2 | G38: =ROUNDUP((G8/G37),0) -> 3 | H38: =ROUNDUP((H8/H37),0) -> 2 | I38: =ROUNDUP((I8/I37),0) -> 1 | J38: =ROUNDUP((J8/J37),0) -> 3 | K38: =ROUNDUP((K8/K37),0) -> 2 | L38: =ROUNDUP((L8/L37),0) -> 2 | M38: =ROUNDUP((M8/M37),0) -> 3 | ... Q38: =ROUNDUP((Q8/Q37),0) -> 0
B39: Функциональное назначение объекта | C39: Встроенно-пристроенные помещения коммерческого использования на первых этажах
B40: Показатель суммарной поэтажной площади объекта на одно место остановки в соответствии с таблицей к Приложению 8 | C40: S1 | D40: =LOOKUP(C39,Таблицы!B148:B153,Таблицы!D148:D153) -> 450 | F40: =$D40 -> 450 | G40: =$D40 -> 450 | H40: =$D40 -> 450 | I40: =$D40 -> 450 | J40: =$D40 -> 450 | K40: =$D40 -> 450 | L40: =$D40 -> 450 | M40: =$D40 -> 450 | ... Q40: =$D40 -> 450
...

Sheet Расчеты_благо
A2: Расчёты благоустройства | G2: Строгино_Среда_к3 | J2: Строгино_Среда_к3.1-3.4 | L2: Строгино_Среда_к3.4-3.7 | N2: Строгино_Среда_к2.1 | P2: Строгино_Среда_к2.2 | R2: Строгино_Среда_к4.1 | T2: Строгино_Среда_к4.2 | V2: ЛЛМЗк.19
E3: Показтель | F3: Ед.изм. | G3: Значение | I3: Ед.изм. | J3: Значение | L3: Значение | N3: Значение | P3: Значение | R3: Значение | T3: Значение | V3: Значение
E4: Общая площадь квартир | F4: кв.м | G4: =LOOKUP($G$2,Расчёт_м_м!E$1:AT$1,Расчёт_м_м!E8:AT8) -> 51539.3 | I4: кв.м | J4: =LOOKUP(J$2,Расчёт_м_м!$E$1:$AT1,Расчёт_м_м!$E8:$AT8) -> 28124.7 | L4: =LOOKUP(L$2,Расчёт_м_м!$E$1:AV$1,Расчёт_м_м!$E8:$AT8) -> 23414.6 | N4: =LOOKUP(N$2,Расчёт_м_м!$E$1:AX$1,Расчёт_м_м!$E8:$AT8) -> 30089 | P4: =LOOKUP(P$2,Расчёт_м_м!$E$1:AZ$1,Расчёт_м_м!$E8:$AT8) -> 17431 | R4: =LOOKUP(R$2,Расчёт_м_м!$E$1:BB$1,Расчёт_м_м!$E8:$AT8) -> 24133 | T4: =LOOKUP(T$2,Расчёт_м_м!$E$1:BD$1,Расчёт_м_м!$E8:$AT8) -> 30991 | V4: =LOOKUP(V$2,Расчёт_м_м!$E$1:BF$1,Расчёт_м_м!$E8:$AT8) -> #N/A
E5: Удел.показатель для жилой части (для расчёта по СП476) | F5: кв.м/чел. | G5: 28 | I5: кв.м/чел. | J5: 28 | L5: 28 | N5: 28 | P5: 28 | R5: 28 | T5: 28 | V5: 28
E6: Жители | F6: чел. | G6: =ROUNDUP(G4/G5,0) -> 1841 | I6: чел. | J6: =ROUNDUP(J4/J5,0) -> 1005 | L6: =ROUNDUP(L4/L5,0) -> 837 | N6: =ROUNDUP(N4/N5,0) -> 1075 | P6: =ROUNDUP(P4/P5,0) -> 623 | R6: =ROUNDUP(R4/R5,0) -> 862 | T6: =ROUNDUP(T4/T5,0) -> 1107 | V6: =ROUNDUP(V4/V5,0) -> #N/A
E7: НПКИ | F7: кв.м | G7: =LOOKUP($G$2,Расчёт_м_м!E$1:AT$1,Расчёт_м_м!E10:AT10) -> 3020.54 | I7: кв.м | J7: =LOOKUP(J$2,Расчёт_м_м!$E$1:AT$1,Расчёт_м_м!$E10:$AT10) -> 1998.51 | L7: =LOOKUP(L$2,Расчёт_м_м!$E$1:AV$1,Расчёт_м_м!$E10:$AT10) -> 1022.03 | N7: =LOOKUP(N$2,Расчёт_м_м!$E$1:AX$1,Расчёт_м_м!$E10:$AT10) -> 1120 | P7: =LOOKUP(P$2,Расчёт_м_м!$E$1:AZ$1,Расчёт_м_м!$E10:$AT10) -> 1367 | R7: =LOOKUP(R$2,Расчёт_м_м!$E$1:BB$1,Расчёт_м_м!$E10:$AT10) -> 3466 | T7: =LOOKUP(T$2,Расчёт_м_м!$E$1:BD$1,Расчёт_м_м!$E10:$AT10) -> 1335 | V7: =LOOKUP(V$2,Расчёт_м_м!$E$1:BF$1,Расчёт_м_м!$E10:$AT10) -> #N/A
E8: Удел.показатель для НПКИ | F8: кв.м/чел. | G8: 20 | I8: кв.м/чел. | J8: 20 | L8: 20 | N8: 20 | P8: 20 | R8: 20 | T8: 20 | V8: 30
E9: Сотрудники НПКИ | F9: чел. | G9: =ROUNDUP(G7/G8,0) -> 152 | I9: чел. | J9: =ROUNDUP(J7/J8,0) -> 100 | L9: =ROUNDUP(L7/L8,0) -> 52 | N9: =ROUNDUP(N7/N8,0) -> 56 | P9: =ROUNDUP(P7/P8,0) -> 69 | R9: =ROUNDUP(R7/R8,0) -> 174 | T9: =ROUNDUP(T7/T8,0) -> 67 | V9: =ROUNDUP(V7/V8,0) -> #N/A
E10: Стоянки постоянного храрения | F10: шт. | G10: =LOOKUP($G$2,Расчёт_м_м!E$1:AT$1,Расчёт_м_м!E70:AT70) -> 411 | I10: шт. | J10: =LOOKUP(J$2,Расчёт_м_м!$E$1:AV$1,Расчёт_м_м!$E70:$E70) -> 244 | L10: =LOOKUP(L$2,Расчёт_м_м!$E$1:AX$1,Расчёт_м_м!$E70:$E70) -> 198 | N10: =LOOKUP(N$2,Расчёт_м_м!$E$1:AZ$1,Расчёт_м_м!$E70:$E70) -> 233 | P10: =LOOKUP(P$2,Расчёт_м_м!$E$1:BB$1,Расчёт_м_м!$E70:$E70) -> 135 | R10: =LOOKUP(R$2,Расчёт_м_м!$E$1:BD$1,Расчёт_м_м!$E70:$E70) -> 219 | T10: =LOOKUP(T$2,Расчёт_м_м!$E$1:BF$1,Расчёт_м_м!$E70:$E70) -> 256 | V10: =LOOKUP(V$2,Расчёт_м_м!$E$1:BH$1,Расчёт_м_м!$R45:$AV45) -> #N/A
E11: Плоскостные стоянки | F11: шт. | G11: =LOOKUP(G$2,Расчёт_м_м!E$1:AT$1,Расчёт_м_м!E51:AT51)+LOOKUP(G$2,Расчёт_м_м!E$1:AT$1,Расчёт_м_м!E52:AT52)+LOOKUP(G$2,Расчёт_м_м!E$1:AT$1,Расчёт_м_м!E53:AT53) -> 1 | I11: шт. | J11: =LOOKUP(J$2,Расчёт_м_м!$E$1:AT$1,Расчёт_м_м!$E51:AT51)+LOOKUP(J$2,Расчёт_м_м!$E$1:AT$1,Расчёт_м_м!$E52:AT52)+LOOKUP(J$2,Расчёт_м_м!$E$1:AT$1,Расчёт_м_м!$E53:AT53) -> 0 | L11: =LOOKUP(L$2,Расчёт_м_м!$E$1:AV$1,Расчёт_м_м!$E51:AV51)+LOOKUP(L$2,Расчёт_м_м!$E$1:AV$1,Расчёт_м_м!$E52:AV52)+LOOKUP(L$2,Расчёт_м_м!$E$1:AV$1,Расчёт_м_м!$E53:AV53) -> 0 | N11: =LOOKUP(N$2,Расчёт_м_м!$E$1:AX$1,Расчёт_м_м!$E51:AX51)+LOOKUP(N$2,Расчёт_м_м!$E$1:AX$1,Расчёт_м_м!$E52:AX52)+LOOKUP(N$2,Расчёт_м_м!$E$1:AX$1,Расчёт_м_м!$E53:AX53) -> 0 | P11: =LOOKUP(P$2,Расчёт_м_м!$E$1:AZ$1,Расчёт_м_м!$E51:AZ51)+LOOKUP(P$2,Расчёт_м_м!$E$1:AZ$1,Расчёт_м_м!$E52:AZ52)+LOOKUP(P$2,Расчёт_м_м!$E$1:AZ$1,Расчёт_м_м!$E53:AZ53) -> 0 | R11: =LOOKUP(R$2,Расчёт_м_м!$E$1:BB$1,Расчёт_м_м!$E51:BB51)+LOOKUP(R$2,Расчёт_м_м!$E$1:BB$1,Расчёт_м_м!$E52:BB52)+LOOKUP(R$2,Расчёт_м_м!$E$1:BB$1,Расчёт_м_м!$E53:BB53) -> 0 | T11: =LOOKUP(T$2,Расчёт_м_м!$E$1:BD$1,Расчёт_м_м!$E51:BD51)+LOOKUP(T$2,Расчёт_м_м!$E$1:BD$1,Расчёт_м_м!$E52:BD52)+LOOKUP(T$2,Расчёт_м_м!$E$1:BD$1,Расчёт_м_м!$E53:BD53) -> 0 | V11: =LOOKUP(V$2,Расчёт_м_м!$E1:$AT1,Расчёт_м_м!$R47:$AT47)+LOOKUP(V2,Расчёт_м_м!$E1:$AT1,Расчёт_м_м!$R48:$AT48) -> #N/A
E12: Площадь участка по ГПЗУ | F12: кв.м | G12: =LOOKUP($G$2,Расчёт_м_м!E$1:AT$1,Расчёт_м_м!E6:AT6) -> 24274.11 | I12: кв.м | J12: =LOOKUP(J$2,Расчёт_м_м!$E1:AT$1,Расчёт_м_м!$E6:$AT6) -> 16700 | L12: =LOOKUP(L$2,Расчёт_м_м!$E1:AV$1,Расчёт_м_м!$E6:$AT6) -> 7574.11 | N12: =LOOKUP(N$2,Расчёт_м_м!$E1:AX$1,Расчёт_м_м!$E6:$AT6) -> 12150 | P12: =LOOKUP(P$2,Расчёт_м_м!$E1:AZ$1,Расчёт_м_м!$E6:$AT6) -> 5118.05 | R12: =LOOKUP(R$2,Расчёт_м_м!$E1:BB$1,Расчёт_м_м!$E6:$AT6) -> 16100 | T12: =LOOKUP(T$2,Расчёт_м_м!$E1:BD$1,Расчёт_м_м!$E6:$AT6) -> 8432.67 | V12: =LOOKUP(V$2,Расчёт_м_м!$E1:BF$1,Расчёт_м_м!$E6:$AT6) -> #N/A
E13: Суммарный объем контейнеров | F13: куб.м | G13: =ROUNDUP(G17,0) -> 16 | I13: куб.м | J13: =ROUNDUP(J17,0) -> 9 | L13: =ROUNDUP(L17,0) -> 7 | N13: =ROUNDUP(N17,0) -> 9 | P13: =ROUNDUP(P17,0) -> 6 | R13: =ROUNDUP(R17,0) -> 8 | T13: =ROUNDUP(T17,0) -> 10 | V13: =ROUNDUP(V17,0) -> #N/A
E14: Предварительная вместимость контейнера | F14: куб.м | G14: 1.1 | I14: куб.м | J14: 1.1 | L14: 1.1 | N14: 1.1 | P14: 1.1 | R14: 1.1 | T14: 1.1 | V14: 1.1
E15: Число контейнеров заданной вместимости | F15: шт. | G15: =ROUNDUP(G13/G14,0) -> 15 | I15: шт. | J15: =ROUNDUP(J13/J14,0) -> 9 | L15: =ROUNDUP(L13/L14,0) -> 7 | N15: =ROUNDUP(N13/N14,0) -> 9 | P15: =ROUNDUP(P13/P14,0) -> 6 | R15: =ROUNDUP(R13/R14,0) -> 8 | T15: =ROUNDUP(T13/T14,0) -> 10 | V15: =ROUNDUP(V13/V14,0) -> #N/A
A16: Группа | B16: N | C16: Наименование категории объектов по Расопряжению ЖКХ г.Москвы от 29 сентября 2021 года N 01-01-14-194/21 | D16: Расчетная единица, в отношении которой | E16: Среднегодовой норматив накопления ТКО | G16: Показатель объекта
F17: Ежедневный объем накопления, куб.м | G17: =G19/365 -> 15.511795 | J17: =J19/365 -> 8.53712 | L17: =L19/365 -> 6.9963901 | N17: =N19/365 -> 8.9377479 | P17: =P19/365 -> 5.3031836 | R17: =R19/365 -> 7.6350959 | T17: =T19/365 -> 9.2495014 | V17: =V19/365 -> #N/A
F18: Фактичекое значение | G18: Годовой объем накопления, куб.м | J18: Годовой объем накопления, куб.м | L18: Годовой объем накопления, куб.м | N18: Годовой объем накопления, куб.м | P18: Годовой объем накопления, куб.м | R18: Годовой объем накопления, куб.м | T18: Годовой объем накопления, куб.м | V18: Годовой объем накопления, куб.м
A19: 1 | B19: 2 | C19: 3 | D19: 4 | E19: 5 | G19: =SUM(G20:G64) -> 5661.8052 | J19: =SUM(J20:J64) -> 3116.0488 | L19: =SUM(L20:L64) -> 2553.6824 | N19: =SUM(N20:N64) -> 3262.278 | P19: =SUM(P20:P64) -> 1935.662 | R19: =SUM(R20:R64) -> 2786.81 | T19: =SUM(T20:T64) -> 3376.068 | V19: =SUM(V20:V64) -> #N/A
A20: I. Административные здания, учреждения, конторы | B20: 1 | C20: Научно-исследовательские, проектные институты и конструкторские бюро | D20: 1 сотрудник | E20: 1.129 | G20: =$E20*F20 -> 0 | J20: =$E20*I20 -> 0 | L20: =$E20*K20 -> 0 | N20: =$E20*M20 -> 0 | P20: =$E20*O20 -> 0 | R20: =$E20*Q20 -> 0 | T20: =$E20*S20 -> 0 | V20: =$E20*U20 -> 0
B21: 2 | C21: Банки и финансовые учреждения | D21: 1 сотрудник | E21: 0.984 | G21: =$E21*F21 -> 0 | J21: =$E21*I21 -> 0 | L21: =$E21*K21 -> 0 | N21: =$E21*M21 -> 0 | P21: =$E21*O21 -> 0 | R21: =$E21*Q21 -> 0 | T21: =$E21*S21 -> 0 | V21: =$E21*U21 -> 0
B22: 3 | C22: Отделения связи | D22: 1 сотрудник | E22: 4.826 | G22: =$E22*F22 -> 0 | J22: =$E22*I22 -> 0 | L22: =$E22*K22 -> 0 | N22: =$E22*M22 -> 0 | P22: =$E22*O22 -> 0 | R22: =$E22*Q22 -> 0 | T22: =$E22*S22 -> 0 | V22: =$E22*U22 -> 0
B23: 4 | C23: Административные, офисные учреждения | D23: 1 сотрудник | E23: 1.252 | F23: =G9 -> 152 | G23: =$E23*F23 -> 190.304 | I23: =J9 -> 100 | J23: =$E23*I23 -> 125.2 | K23: =L9 -> 52 | L23: =$E23*K23 -> 65.104 | M23: =N9 -> 56 | N23: =$E23*M23 -> 70.112 | O23: =P9 -> 69 | P23: =$E23*O23 -> 86.388 | Q23: =R9 -> 174 | R23: =$E23*Q23 -> 217.848 | S23: =T9 -> 67 | T23: =$E23*S23 -> 83.884 | U23: =V9 -> #N/A | V23: =$E23*U23 -> #N/A
A24: II. Предприятия торговли | B24: 5 | C24: Продовольственные магазины | D24: 1 кв.м площади | E24: 0.41 | G24: =$E24*F24 -> 0 | J24: =$E24*I24 -> 0 | L24: =$E24*K24 -> 0 | N24: =$E24*M24 -> 0 | P24: =$E24*O24 -> 0 | R24: =$E24*Q24 -> 0 | T24: =$E24*S24 -> 0 | V24: =$E24*U24 -> 0
B25: 6 | C25: Промтоварные магазины | D25: 1 кв.м площади | E25: 0.24 | G25: =$E25*F25 -> 0 | J25: =$E25*I25 -> 0 | L25: =$E25*K25 -> 0 | N25: =$E25*M25 -> 0 | P25: =$E25*O25 -> 0 | R25: =$E25*Q25 -> 0 | T25: =$E25*S25 -> 0 | V25: =$E25*U25 -> 0
B26: 7 | C26: Павильоны | D26: 1 кв.м площади | E26: 0.676 | G26: =$E26*F26 -> 0 | J26: =$E26*I26 -> 0 | L26: =$E26*K26 -> 0 | N26: =$E26*M26 -> 0 | P26: =$E26*O26 -> 0 | R26: =$E26*Q26 -> 0 | T26: =$E26*S26 -> 0 | V26: =$E26*U26 -> 0
B27: 8 | C27: Палатки, киоски | D27: 1 кв.м площади | E27: 0.82 | G27: =$E27*F27 -> 0 | J27: =$E27*I27 -> 0 | L27: =$E27*K27 -> 0 | N27: =$E27*M27 -> 0 | P27: =$E27*O27 -> 0 | R27: =$E27*Q27 -> 0 | T27: =$E27*S27 -> 0 | V27: =$E27*U27 -> 0
B28: 9 | C28: Супермаркеты | D28: 1 кв.м площади | E28: 0.19 | G28: =$E28*F28 -> 0 | J28: =$E28*I28 -> 0 | L28: =$E28*K28 -> 0 | N28: =$E28*M28 -> 0 | P28: =$E28*O28 -> 0 | R28: =$E28*Q28 -> 0 | T28: =$E28*S28 -> 0 | V28: =$E28*U28 -> 0
B29: 10 | C29: Рынки продовольственные | D29: 1 кв.м площади | E29: 0.335 | G29: =$E29*F29 -> 0 | J29: =$E29*I29 -> 0 | L29: =$E29*K29 -> 0 | N29: =$E29*M29 -> 0 | P29: =$E29*O29 -> 0 | R29: =$E29*Q29 -> 0 | T29: =$E29*S29 -> 0 | V29: =$E29*U29 -> 0
B30: 11 | C30: Рынки промтоварные | D30: 1 кв.м площади | E30: 0.034 | G30: =$E30*F30 -> 0 | J30: =$E30*I30 -> 0 | L30: =$E30*K30 -> 0 | N30: =$E30*M30 -> 0 | P30: =$E30*O30 -> 0 | R30: =$E30*Q30 -> 0 | T30: =$E30*S30 -> 0 | V30: =$E30*U30 -> 0
A31: III. Предприятия транспортной инфраструктуры | B31: 12 | C31: Автомастерские, шиномонтажные мастерские, станции технического обслуживания | D31: 1 машино-место | E31: 1.972 | G31: =$E31*F31 -> 0 | J31: =$E31*I31 -> 0 | L31: =$E31*K31 -> 0 | N31: =$E31*M31 -> 0 | P31: =$E31*O31 -> 0 | R31: =$E31*Q31 -> 0 | T31: =$E31*S31 -> 0 | V31: =$E31*U31 -> 0
B32: 13 | C32: Автозаправочные станции | D32: 1 пост | E32: 7.433 | G32: =$E32*F32 -> 0 | J32: =$E32*I32 -> 0 | L32: =$E32*K32 -> 0 | N32: =$E32*M32 -> 0 | P32: =$E32*O32 -> 0 | R32: =$E32*Q32 -> 0 | T32: =$E32*S32 -> 0 | V32: =$E32*U32 -> 0
B33: 14 | C33: Автостоянки и парковки | D33: 1 машино-место | E33: 0.444 | F33: =G11 -> 1 | G33: =$E33*F33 -> 0.444 | I33: =J11 -> 0 | J33: =$E33*I33 -> 0 | K33: =L11 -> 0 | L33: =$E33*K33 -> 0 | M33: =N11 -> 0 | N33: =$E33*M33 -> 0 | O33: =P11 -> 0 | P33: =$E33*O33 -> 0 | Q33: =R11 -> 0 | R33: =$E33*Q33 -> 0 | S33: =T11 -> 0 | T33: =$E33*S33 -> 0 | U33: =V11 -> #N/A | V33: =$E33*U33 -> #N/A
B34: 15 | C34: Гаражи, парковки закрытого типа | D34: 1 машино-место | E34: 0.27 | F34: =G10 -> 411 | G34: =$E34*F34 -> 110.97 | I34: =J10 -> 244 | J34: =$E34*I34 -> 65.88 | K34: =L10 -> 198 | L34: =$E34*K34 -> 53.46 | M34: =N10 -> 233 | N34: =$E34*M34 -> 62.91 | O34: =P10 -> 135 | P34: =$E34*O34 -> 36.45 | Q34: =R10 -> 219 | R34: =$E34*Q34 -> 59.13 | S34: =T10 -> 256 | T34: =$E34*S34 -> 69.12 | U34: =V10 -> #N/A | V34: =$E34*U34 -> #N/A
B35: 16 | C35: Автомойки | D35: 1 машино-место | E35: 4.499 | G35: =$E35*F35 -> 0 | J35: =$E35*I35 -> 0 | L35: =$E35*K35 -> 0 | N35: =$E35*M35 -> 0 | P35: =$E35*O35 -> 0 | R35: =$E35*Q35 -> 0 | T35: =$E35*S35 -> 0 | V35: =$E35*U35 -> 0
B36: 17 | C36: Железнодорожные и автовокзалы, аэропорты, речные порты | D36: 1 пассажир | E36: 0.044 | G36: =$E36*F36 -> 0 | J36: =$E36*I36 -> 0 | L36: =$E36*K36 -> 0 | N36: =$E36*M36 -> 0 | P36: =$E36*O36 -> 0 | R36: =$E36*Q36 -> 0 | T36: =$E36*S36 -> 0 | V36: =$E36*U36 -> 0
A37: IV. Дошкольные и учебные учреждения | B37: 18 | C37: Дошкольные образовательные учреждения | D37: 1 место | E37: 0.342 | G37: =$E37*F37 -> 0 | J37: =$E37*I37 -> 0 | L37: =$E37*K37 -> 0 | N37: =$E37*M37 -> 0 | P37: =$E37*O37 -> 0 | R37: =$E37*Q37 -> 0 | T37: =$E37*S37 -> 0 | V37: =$E37*U37 -> 0
B38: 19 | C38: Общеобразовательные, среднеспециальные учреждения и ПТУ | D38: 1 место | E38: 0.071 | G38: =$E38*F38 -> 0 | J38: =$E38*I38 -> 0 | L38: =$E38*K38 -> 0 | N38: =$E38*M38 -> 0 | P38: =$E38*O38 -> 0 | R38: =$E38*Q38 -> 0 | T38: =$E38*S38 -> 0 | V38: =$E38*U38 -> 0
B39: 20 | C39: Высшие учебные заведения | D39: 1 место | E39: 0.101 | G39: =$E39*F39 -> 0 | J39: =$E39*I39 -> 0 | L39: =$E39*K39 -> 0 | N39: =$E39*M39 -> 0 | P39: =$E39*O39 -> 0 | R39: =$E39*Q39 -> 0 | T39: =$E39*S39 -> 0 | V39: =$E39*U39 -> 0
B40: 21 | C40: Образовательные учреждения дополнительного образования | D40: 1 место | E40: 0.666 | G40: =$E40*F40 -> 0 | J40: =$E40*I40 -> 0 | L40: =$E40*K40 -> 0 | N40: =$E40*M40 -> 0 | P40: =$E40*O40 -> 0 | R40: =$E40*Q40 -> 0 | T40: =$E40*S40 -> 0 | V40: =$E40*U40 -> 0
B41: 22 | C41: Детские дома, школы-интернаты | D41: 1 место | E41: 0.094 | G41: =$E41*F41 -> 0 | J41: =$E41*I41 -> 0 | L41: =$E41*K41 -> 0 | N41: =$E41*M41 -> 0 | P41: =$E41*O41 -> 0 | R41: =$E41*Q41 -> 0 | T41: =$E41*S41 -> 0 | V41: =$E41*U41 -> 0
...

Sheet Расчёт (ХП)
A1: Расчёт стоянок выполнен на основании ПП №945-ПП г. Москвы
A2: Исходные данные | C2: Район | D2: 3.7. Покровское-Стрешнево. | E2: Зона урбанизации согласно приложения 2 РНГПТ | G2: =LOOKUP(D2,'Справочные данные'!A59:A202,'Справочные данные'!B59:B202) -> Т3
A3: Уточняющий коэффициент урбанизации территории города Москвы, согласно Приложения 3, К3 | G3: =LOOKUP(G2,'Справочные данные'!A3:A6,'Справочные данные'!B3:B6) -> 0.75
A4: ="Фактическая удалённость до скоростного внеуличного транспорта (т.к. "&A2&" ) по ситуационной схеме" -> Фактическая удалённость до скоростного внеуличного транспорта (т.к. Исходные данные ) по ситуационной схеме | F4: Более 700м
A5: =LOOKUP(F4,'Справочные данные'!B209:B210,'Справочные данные'!C209:C210) -> Проектируемый Объект попадает только в зону доступности наземного городского пассажирского транспорта (магистральная УДС, на которой организовано движение наземного городского транспорта - не далее 500м); а скоростной внеуличный транспорт (метрополитен и скоростной трамвай) расположен далее 700м; ввиду этого, согласно Приложения 7 РНГПТ, принят коэффициент К2 | G5: =LOOKUP(F4,'Справочные данные'!B209:B210,'Справочные данные'!D209:D210) -> 0.85
A6: Таблица балльной оценки уровня потребности в местах постоянного хранения автомобилей
A7: N п/п | B7: Критерий оценки потребности в местах постоянного хранения автомобилей (i) | C7: Максимальный балл по критерию | D7: Показатели | E7: Значения | F7: Весовой коэффициент к максимальному баллу по критерию i (ki) | G7: Расчетный критерий (3)*(6)
A8: 1 | B8: 2 | C8: 3 | D8: 4 | E8: 5 | F8: 6 | G8: 7
A9: 1 | B9: Доступность наземного городского пассажирского транспорта (НГПТ) | C9: 5 | D9: Число остановок различных маршрутов НГПТ в пешей доступности (до 500 м) | E9: 1 и менее | F9: =LOOKUP(E9,'Справочные данные'!A9:A11,'Справочные данные'!B9:B11) -> 1 | G9: =""&C9&"*"&F9&"="&C9*F9&"" -> 5*1=5 | H9: =C9*F9 -> 5
A10: 2 | B10: Интенсивность движения НГПТ | C10: 5 | D10: Интервалы движения | E10: Более 20 минут | F10: =LOOKUP(E10,'Справочные данные'!A14:A17,'Справочные данные'!B14:B17) -> 1 | G10: =""&C10&"*"&F10&"="&C10*F10&"" -> 5*1=5 | H10: =C10*F10 -> 5
A11: 3 | B11: Доступность станций метрополитена | C11: 15 | D11: Радиус доступности станций метрополитена | E11: Более 700м - не более 1200м | F11: =LOOKUP(E11,'Справочные данные'!A20:A23,'Справочные данные'!B20:B23) -> 0.25 | G11: =""&C11&"*"&F11&"="&C11*F11&"" -> 15*0.25=3.75 | H11: =C11*F11 -> 3.75
A12: 4 | B12: Доступность станций железнодорожного транспорта | C12: 15 | D12: Радиус доступности станций железнодорожного транспорта | E12: Более 1200м - не более 2500м | F12: =LOOKUP(E12,'Справочные данные'!A26:A29,'Справочные данные'!B26:B29) -> 0.5 | G12: =""&C12&"*"&F12&"="&C12*F12&"" -> 15*0.5=7.5 | H12: =C12*F12 -> 7.5
A13: 5 | B13: Тип жилой застройки по уровню комфорта | C13: 20 | D13: Премиум и бизнес-класс | F13: =LOOKUP(D13,'Справочные данные'!A32:A36,'Справочные данные'!B32:B36) -> 1 | G13: =""&C13&"*"&F13&"="&C13*F13&"" -> 20*1=20 | H13: =C13*F13 -> 20
A14: 6 | B14: Плотность застройки:
A15: 6.1 | B15: Плотность застройки в границах планировочного квартала | C15: 20 | D15: - (не учитывается, т.к. рассматривается отдельный з.у.) | F15: =LOOKUP(D15,'Справочные данные'!A39:A43,'Справочные данные'!B39:B43) -> 0 | G15: =""&C15&"*"&F15&"="&C15*F15&"" -> 20*0=0 | H15: =C15*F15 -> 0
A16: 6.2 | B16: Плотность застройки в границах земельного участка | C16: 20 | D16: 15000 м /га - менее 20000 кв.м/га | F16: =LOOKUP(D16,'Справочные данные'!A46:A50,'Справочные данные'!B46:B50) -> 0.75 | G16: =""&C16&"*"&F16&"="&C16*F16&"" -> 20*0.75=15 | H16: =C16*F16 -> 15
A17: 7 | B17: Уточняющий коэффициент урбанизации территории города Москвы при расчете числа мест постоянного хранения автомобилей | C17: 20 | D17: =G2 -> Т3 | F17: =LOOKUP(D17,'Справочные данные'!A3:A6,'Справочные данные'!B53:B56) -> 0.5 | G17: =""&C17&"*"&F17&"="&C17*F17&"" -> 20*0.5=10 | H17: =C17*F17 -> 10
A18: Балльная оценка уровня потребности в местах постоянного хранения автомобилей Бп | G18: =SUM(H9:H17) -> 66.25
A19: ="По итогам расчета балльной оценки уровня потребности в местах постоянного хранения автомобилей ("&G18&" баллов) принят, согласно п. 6.2.5 РНГПТ, коэффициент обеспеченности Объекта машино-местами для постоянного хранения индивидуального транспорта КБп" -> По итогам расчета балльной оценки уровня потребности в местах постоянного хранения автомобилей (66.25 баллов) принят, согласно п. 6.2.5 РНГПТ, коэффициент обеспеченности Объекта машино-местами для постоянного хранения индивидуального транспорта КБп | G19: =IF(G18>75,0.7,IF(OR(G18=50,G18<50),0.5,0.6)) -> 0.6

Sheet Расчёт (ММ)
A1: Расчёт стоянок выполнен на основании ПП №945-ПП г. Москвы
A2: Исходные данные | C2: Район | D2: 2.27. Митино. | E2: Зона урбанизации согласно приложения 2 РНГПТ | G2: =LOOKUP(D2,'Справочные данные'!A59:A202,'Справочные данные'!B59:B202) -> Т2
A3: Уточняющий коэффициент урбанизации территории города Москвы, согласно Приложения 3, К3 | G3: =LOOKUP(G2,'Справочные данные'!A3:A6,'Справочные данные'!B3:B6) -> 0.85
A4: ="Фактическая удалённость до скоростного внеуличного транспорта (т.к. "&A2&" ) по ситуационной схеме" -> Фактическая удалённость до скоростного внеуличного транспорта (т.к. Исходные данные ) по ситуационной схеме | F4: Более 700м
A5: =LOOKUP(F4,'Справочные данные'!B209:B210,'Справочные данные'!C209:C210) -> Проектируемый Объект попадает только в зону доступности наземного городского пассажирского транспорта (магистральная УДС, на которой организовано движение наземного городского транспорта - не далее 500м); а скоростной внеуличный транспорт (метрополитен и скоростной трамвай) расположен далее 700м; ввиду этого, согласно Приложения 7 РНГПТ, принят коэффициент К2 | G5: =LOOKUP(F4,'Справочные данные'!B209:B210,'Справочные данные'!D209:D210) -> 0.85
A6: Таблица балльной оценки уровня потребности в местах постоянного хранения автомобилей
A7: N п/п | B7: Критерий оценки потребности в местах постоянного хранения автомобилей (i) | C7: Максимальный балл по критерию | D7: Показатели | E7: Значения | F7: Весовой коэффициент к максимальному баллу по критерию i (ki) | G7: Расчетный критерий (3)*(6)
A8: 1 | B8: 2 | C8: 3 | D8: 4 | E8: 5 | F8: 6 | G8: 7
A9: 1 | B9: Доступность наземного городского пассажирского транспорта (НГПТ) | C9: 5 | D9: Число остановок различных маршрутов НГПТ в пешей доступности (до 500 м) | E9: 1 и менее | F9: =LOOKUP(E9,'Справочные данные'!A9:A11,'Справочные данные'!B9:B11) -> 1 | G9: =""&C9&"*"&F9&"="&C9*F9&"" -> 5*1=5 | H9: =C9*F9 -> 5
A10: 2 | B10: Интенсивность движения НГПТ | C10: 5 | D10: Интервалы движения | E10: Более 20 минут | F10: =LOOKUP(E10,'Справочные данные'!A14:A17,'Справочные данные'!B14:B17) -> 1 | G10: =""&C10&"*"&F10&"="&C10*F10&"" -> 5*1=5 | H10: =C10*F10 -> 5
A11: 3 | B11: Доступность станций метрополитена | C11: 15 | D11: Радиус доступности станций метрополитена | E11: Более 700м - не более 1200м | F11: =LOOKUP(E11,'Справочные данные'!A20:A23,'Справочные данные'!B20:B23) -> 0.25 | G11: =""&C11&"*"&F11&"="&C11*F11&"" -> 15*0.25=3.75 | H11: =C11*F11 -> 3.75
A12: 4 | B12: Доступность станций железнодорожного транспорта | C12: 15 | D12: Радиус доступности станций железнодорожного транспорта | E12: Более 1200м - не более 2500м | F12: =LOOKUP(E12,'Справочные данные'!A26:A29,'Справочные данные'!B26:B29) -> 0.5 | G12: =""&C12&"*"&F12&"="&C12*F12&"" -> 15*0.5=7.5 | H12: =C12*F12 -> 7.5
A13: 5 | B13: Тип жилой застройки по уровню комфорта | C13: 20 | D13: Премиум и бизнес-класс | F13: =LOOKUP(D13,'Справочные данные'!A32:A36,'Справочные данные'!B32:B36) -> 1 | G13: =""&C13&"*"&F13&"="&C13*F13&"" -> 20*1=20 | H13: =C13*F13 -> 20
A14: 6 | B14: Плотность застройки:
A15: 6.1 | B15: Плотность застройки в границах планировочного квартала | C15: 20 | D15: - (не учитывается, т.к. рассматривается отдельный з.у.) | F15: =LOOKUP(D15,'Справочные данные'!A39:A43,'Справочные данные'!B39:B43) -> 0 | G15: =""&C15&"*"&F15&"="&C15*F15&"" -> 20*0=0 | H15: =C15*F15 -> 0
A16: 6.2 | B16: Плотность застройки в границах земельного участка | C16: 20 | D16: 15000 м /га - менее 20000 кв.м/га | F16: =LOOKUP(D16,'Справочные данные'!A46:A50,'Справочные данные'!B46:B50) -> 0.75 | G16: =""&C16&"*"&F16&"="&C16*F16&"" -> 20*0.75=15 | H16: =C16*F16 -> 15
A17: 7 | B17: Уточняющий коэффициент урбанизации территории города Москвы при расчете числа мест постоянного хранения автомобилей | C17: 20 | D17: =G2 -> Т2 | F17: =LOOKUP(D17,'Справочные данные'!A3:A6,'Справочные данные'!B53:B56) -> 0.75 | G17: =""&C17&"*"&F17&"="&C17*F17&"" -> 20*0.75=15 | H17: =C17*F17 -> 15
A18: Балльная оценка уровня потребности в местах постоянного хранения автомобилей Бп | G18: =SUM(H9:H17) -> 71.25
A19: ="По итогам расчета балльной оценки уровня потребности в местах постоянного хранения автомобилей ("&G18&" баллов) принят, согласно п. 6.2.5 РНГПТ, коэффициент обеспеченности Объекта машино-местами для постоянного хранения индивидуального транспорта КБп" -> По итогам расчета балльной оценки уровня потребности в местах постоянного хранения автомобилей (71.25 баллов) принят, согласно п. 6.2.5 РНГПТ, коэффициент обеспеченности Объекта машино-местами для постоянного хранения индивидуального транспорта КБп | G19: =IF(G18>75,0.7,IF(OR(G18=50,G18<50),0.5,0.6)) -> 0.6

Sheet Расчёт (ллмз3)
A1: Расчёт стоянок выполнен на основании ПП №945-ПП г. Москвы
A2: Исходные данные | C2: Район | D2: 1.26. Люблино. | E2: Зона урбанизации согласно приложения 2 РНГПТ | G2: =LOOKUP(D2,'Справочные данные'!A59:A202,'Справочные данные'!B59:B202) -> Т1
A3: Уточняющий коэффициент урбанизации территории города Москвы, согласно Приложения 3, К3 | G3: =LOOKUP(G2,'Справочные данные'!A3:A6,'Справочные данные'!B3:B6) -> 1
A4: ="Фактическая удалённость до скоростного внеуличного транспорта (т.к. "&A2&" ) по ситуационной схеме" -> Фактическая удалённость до скоростного внеуличного транспорта (т.к. Исходные данные ) по ситуационной схеме | F4: Не более 700м
A5: =LOOKUP(F4,'Справочные данные'!B209:B210,'Справочные данные'!C209:C210) -> Проектируемый Объект попадает в зону доступности как городского пассажирского транспорта (магистральная УДС, на которой организовано движение наземного городского транспорта - не далее 500м), так и скоростного внеуличного транспорта (метрополитен или скоростной трамвай - не далее 700м); ввиду этого, согласно Приложения 7 РНГПТ, принят коэффициент К2 | G5: =LOOKUP(F4,'Справочные данные'!B209:B210,'Справочные данные'!D209:D210) -> 0.7
A6: Таблица балльной оценки уровня потребности в местах постоянного хранения автомобилей
A7: N п/п | B7: Критерий оценки потребности в местах постоянного хранения автомобилей (i) | C7: Максимальный балл по критерию | D7: Показатели | E7: Значения | F7: Весовой коэффициент к максимальному баллу по критерию i (ki) | G7: Расчетный критерий (3)*(6)
A8: 1 | B8: 2 | C8: 3 | D8: 4 | E8: 5 | F8: 6 | G8: 7
A9: 1 | B9: Доступность наземного городского пассажирского транспорта (НГПТ) | C9: 5 | D9: Число остановок различных маршрутов НГПТ в пешей доступности (до 500 м) | E9: 1 и менее | F9: =LOOKUP(E9,'Справочные данные'!A9:A11,'Справочные данные'!B9:B11) -> 1 | G9: =""&C9&"*"&F9&"="&C9*F9&"" -> 5*1=5 | H9: =C9*F9 -> 5
A10: 2 | B10: Интенсивность движения НГПТ | C10: 5 | D10: Интервалы движения | E10: Более 20 минут | F10: =LOOKUP(E10,'Справочные данные'!A14:A17,'Справочные данные'!B14:B17) -> 1 | G10: =""&C10&"*"&F10&"="&C10*F10&"" -> 5*1=5 | H10: =C10*F10 -> 5
A11: 3 | B11: Доступность станций метрополитена | C11: 15 | D11: Радиус доступности станций метрополитена | E11: Не более 700м | F11: =LOOKUP(E11,'Справочные данные'!A20:A23,'Справочные данные'!B20:B23) -> 0 | G11: =""&C11&"*"&F11&"="&C11*F11&"" -> 15*0=0 | H11: =C11*F11 -> 0
A12: 4 | B12: Доступность станций железнодорожного транспорта | C12: 15 | D12: Радиус доступности станций железнодорожного транспорта | E12: Более 1200м - не более 2500м | F12: =LOOKUP(E12,'Справочные данные'!A26:A29,'Справочные данные'!B26:B29) -> 0.5 | G12: =""&C12&"*"&F12&"="&C12*F12&"" -> 15*0.5=7.5 | H12: =C12*F12 -> 7.5
A13: 5 | B13: Тип жилой застройки по уровню комфорта | C13: 20 | D13: Премиум и бизнес-класс | F13: =LOOKUP(D13,'Справочные данные'!A32:A36,'Справочные данные'!B32:B36) -> 1 | G13: =""&C13&"*"&F13&"="&C13*F13&"" -> 20*1=20 | H13: =C13*F13 -> 20
A14: 6 | B14: Плотность застройки:
A15: 6.1 | B15: Плотность застройки в границах планировочного квартала | C15: 20 | D15: - (не учитывается, т.к. рассматривается отдельный з.у.) | F15: =LOOKUP(D15,'Справочные данные'!A39:A43,'Справочные данные'!B39:B43) -> 0 | G15: =""&C15&"*"&F15&"="&C15*F15&"" -> 20*0=0 | H15: =C15*F15 -> 0
A16: 6.2 | B16: Плотность застройки в границах земельного участка | C16: 20 | D16: Более 25000 м /га | F16: =LOOKUP(D16,'Справочные данные'!A46:A50,'Справочные данные'!B46:B50) -> 0.25 | G16: =""&C16&"*"&F16&"="&C16*F16&"" -> 20*0.25=5 | H16: =C16*F16 -> 5
A17: 7 | B17: Уточняющий коэффициент урбанизации территории города Москвы при расчете числа мест постоянного хранения автомобилей | C17: 20 | D17: =G2 -> Т1 | F17: =LOOKUP(D17,'Справочные данные'!A3:A6,'Справочные данные'!B53:B56) -> 1 | G17: =""&C17&"*"&F17&"="&C17*F17&"" -> 20*1=20 | H17: =C17*F17 -> 20
A18: Балльная оценка уровня потребности в местах постоянного хранения автомобилей Бп | G18: =SUM(H9:H17) -> 62.5
